Workbook

Sheet Дані
A1: Прізвище | B1: Імя | C1: По-батькова | D1: пол | E1: дата нарождения | F1: відділ | G1: оклад, € | H1: к-ть дітей | I1: Стаж праці | J1: Доплата | K1: Сума на руки | L1: Премія | M1: Рік народження
A2: Антонова | B2: Анна | C2: Миколаївна | D2: ж | E2: 28994 | F2: АПС | G2: 5440 | H2: 0 | I2: 9 | J2: =IF(H2<=1, 111, IF(H2<=3, 278, 454)) -> 111 | K2: =(G2 * 0.87) + J2 -> 4843.8 | L2: =IF(I2 > 10, G2 * 0.3, 250) -> 250 | M2: =YEAR(E2) -> 1979
A3: Протопопов | B3: Владимир | C3: Валентинович | D3: м | E3: 28010 | F3: ТКБ | G3: 1514 | H3: 0 | I3: 22 | J3: =IF(H3<=1, 111, IF(H3<=3, 278, 454)) -> 111 | K3: =(G3 * 0.87) + J3 -> 1428.18 | L3: =IF(I3 > 10, G3 * 0.3, 250) -> 454.2 | M3: =YEAR(E3) -> 1976
A4: Смирнова | B4: Раїса | C4: Івановна | D4: ж | E4: 26504 | F4: ОТД | G4: 1800 | H4: 1 | I4: 11 | J4: =IF(H4<=1, 111, IF(H4<=3, 278, 454)) -> 111 | K4: =(G4 * 0.87) + J4 -> 1677 | L4: =IF(I4 > 10, G4 * 0.3, 250) -> 540 | M4: =YEAR(E4) -> 1972
A5: Андріїв | B5: Віктор | C5: Борисович | D5: м | E5: 26452 | F5: ОТД | G5: 2070 | H5: 1 | I5: 9 | J5: =IF(H5<=1, 111, IF(H5<=3, 278, 454)) -> 111 | K5: =(G5 * 0.87) + J5 -> 1911.9 | L5: =IF(I5 > 10, G5 * 0.3, 250) -> 250 | M5: =YEAR(E5) -> 1972
A6: Сергіїв | B6: Юрій | C6: Іванович | D6: м | E6: 26065 | F6: ОНК | G6: 4000 | H6: 2 | I6: 18 | J6: =IF(H6<=1, 111, IF(H6<=3, 278, 454)) -> 278 | K6: =(G6 * 0.87) + J6 -> 3758 | L6: =IF(I6 > 10, G6 * 0.3, 250) -> 1200 | M6: =YEAR(E6) -> 1971
A7: Кротова | B7: Анна | C7: Григорівна | D7: ж | E7: 25936 | F7: ОНК | G7: 5750 | H7: 1 | I7: 12 | J7: =IF(H7<=1, 111, IF(H7<=3, 278, 454)) -> 111 | K7: =(G7 * 0.87) + J7 -> 5113.5 | L7: =IF(I7 > 10, G7 * 0.3, 250) -> 1725 | M7: =YEAR(E7) -> 1971
A8: Колобова | B8: Ніна | C8: Івановна | D8: ж | E8: 25538 | F8: ОНК | G8: 8500 | H8: 1 | I8: 16 | J8: =IF(H8<=1, 111, IF(H8<=3, 278, 454)) -> 111 | K8: =(G8 * 0.87) + J8 -> 7506 | L8: =IF(I8 > 10, G8 * 0.3, 250) -> 2550 | M8: =YEAR(E8) -> 1969
A9: Крупинов | B9: Александр | C9: Саргійович | D9: м | E9: 25013 | F9: ТКБ | G9: 3600 | H9: 0 | I9: 5 | J9: =IF(H9<=1, 111, IF(H9<=3, 278, 454)) -> 111 | K9: =(G9 * 0.87) + J9 -> 3243 | L9: =IF(I9 > 10, G9 * 0.3, 250) -> 250 | M9: =YEAR(E9) -> 1968
A10: Шичко | B10: Любовь | C10: Васильвівна | D10: ж | E10: 24957 | F10: ОТД | G10: 3060 | H10: 4 | I10: 4 | J10: =IF(H10<=1, 111, IF(H10<=3, 278, 454)) -> 454 | K10: =(G10 * 0.87) + J10 -> 3116.2 | L10: =IF(I10 > 10, G10 * 0.3, 250) -> 250 | M10: =YEAR(E10) -> 1968
A11: Гусев | B11: Миколай | C11: Александрович | D11: м | E11: 24714 | F11: АПС | G11: 7360 | H11: 1 | I11: 21 | J11: =IF(H11<=1, 111, IF(H11<=3, 278, 454)) -> 111 | K11: =(G11 * 0.87) + J11 -> 6514.2 | L11: =IF(I11 > 10, G11 * 0.3, 250) -> 2208 | M11: =YEAR(E11) -> 1967
A12: Грушин | B12: Александр | C12: Владимирович | D12: м | E12: 24630 | F12: ТКБ | G12: 3000 | H12: 0 | I12: 10 | J12: =IF(H12<=1, 111, IF(H12<=3, 278, 454)) -> 111 | K12: =(G12 * 0.87) + J12 -> 2721 | L12: =IF(I12 > 10, G12 * 0.3, 250) -> 250 | M12: =YEAR(E12) -> 1967
A13: Медникова | B13: Вячеслав | C13: Александрович | D13: м | E13: 24033 | F13: ОТД | G13: 905 | H13: 0 | I13: 14 | J13: =IF(H13<=1, 111, IF(H13<=3, 278, 454)) -> 111 | K13: =(G13 * 0.87) + J13 -> 898.35 | L13: =IF(I13 > 10, G13 * 0.3, 250) -> 271.5 | M13: =YEAR(E13) -> 1965
... A69: Платова | B69: Людмила | C69: Пантелеевна | D69: ж | E69: 13430 | F69: ОТД | G69: 1800 | H69: 1 | I69: 9 | J69: =IF(H69<=1, 111, IF(H69<=3, 278, 454)) -> 111 | K69: =(G69 * 0.87) + J69 -> 1677 | L69: =IF(I69 > 10, G69 * 0.3, 250) -> 250 | M69: =YEAR(E69) -> 1936

Sheet Завдання 1
B1: Завдання
B2: 1 | C2: Оформити клітинки різними кольорами заливок відповідно до вимог:
C3: вихідні дні - сітло синім
C4: відпустка - сірим
C5: відрідження - зеленим
C6: лікарняний - жовтим
C7: дні прогулів - червоним
B9: 2 | C9: По рахувати за місяц по віділам (розбивка по відділам на вкладці Дані):
C10: кільксть людей що були у відпустці
C11: кільксть людей що були у відрядженні
C12: кільксть людей що брали лікарняний
C13: кільксть людей що прогуляли дні
C14: загальна кількість годин відпрацьованна відділом
B16: 1
B17: Прізвище І. П. | C17: 44805 | D17: 44806 | E17: 44807 | F17: 44808 | G17: 44809 | H17: 44810 | I17: 44811 | J17: 44812 | K17: 44813 | L17: 44814 | M17: 44815 | N17: 44816 | O17: 44817 | P17: 44818 | Q17: 44819 | R17: 44820 | S17: 44821 | T17: 44822 | U17: 44823 | V17: 44824 | W17: 44825 | X17: 44826 | Y17: 44827 | Z17: 44828 | AA17: 44829 | AB17: 44830 | AC17: 44831 | AD17: 44832 | AE17: 44833 | AF17: 44834 | AG17: Відділ
B18: Антонова А. М | C18: Відпус | D18: в | E18: в | F18: Відпус | G18: Відпус | H18: 8 | I18: 8 | J18: 8 | K18: в | L18: в | M18: Відр | N18: Відр | O18: Відпус | P18: Відпус | Q18: 8 | R18: в | S18: в | T18: 8 | U18: 8 | V18: 8 | W18: 8 | X18: 8 | Y18: в | Z18: в | AA18: 8 | AB18: 8 | AC18: 10 | AD18: 8 | AE18: 8 | AF18: в | AG18: =VLOOKUP(TRIM(LEFT(B18, FIND(" ", B18 & " ")-1)) & "*", Дані!$A$1:$F$70, 6, FALSE) -> АПС | AH18: =$AG$18:$AG$85="АПС" -> TRUE | AI18: =IF(COUNTIF(C18:AF18, "Відпус") > 0, 1, 0) -> 1 | AJ18: =SUMIFS(AH18:AH85,AG18:AG85,"АПС") -> 0
B19: Протопопов В. В | C19: 8 | D19: в | E19: в | F19: Відр | G19: Відр | H19: Відр | I19: Відр | J19: Відр | K19: в | L19: в | M19: 4 | N19: 6 | O19: 8 | P19: 6 | Q19: 4 | R19: в | S19: в | T19: 6 | U19: 8 | V19: 6 | W19: 8 | X19: 6 | Y19: в | Z19: в | AA19: 8 | AB19: 6 | AC19: 8 | AD19: 6 | AE19: 8 | AF19: в | AG19: =VLOOKUP(TRIM(LEFT(B19, FIND(" ", B19 & " ")-1)) & "*", Дані!$A$1:$F$70, 6, FALSE) -> ТКБ | AH19: =$AG$18:$AG$85="АПС" -> FALSE
B20: Смирнова Р. І | C20: 8 | D20: в | E20: в | F20: Відр | G20: Відр | H20: 8 | I20: 6 | J20: 8 | K20: в | L20: в | M20: 8 | N20: 8 | O20: 8 | P20: 8 | Q20: 8 | R20: в | S20: в | T20: 8 | U20: 8 | V20: 8 | W20: Відпус | X20: Відпус | Y20: в | Z20: в | AA20: 8 | AB20: 8 | AC20: 8 | AD20: 8 | AE20: 8 | AF20: в | AG20: =VLOOKUP(TRIM(LEFT(B20, FIND(" ", B20 & " ")-1)) & "*", Дані!$A$1:$F$70, 6, FALSE) -> ОТД | AH20: =$AG$18:$AG$85="АПС" -> FALSE
B21: Андріїв В. Б | C21: 8 | D21: в | E21: в | F21: Відр | G21: Відр | H21: Відр | I21: Відр | J21: 10 | K21: в | L21: в | M21: 4 | N21: 6 | O21: 8 | P21: 6 | Q21: 4 | R21: в | S21: Відр | T21: Відр | U21: Відр | V21: Відр | W21: 8 | X21: 6 | Y21: в | Z21: в | AA21: 8 | AB21: 6 | AC21: 8 | AD21: 6 | AE21: 8 | AF21: в | AG21: =VLOOKUP(TRIM(LEFT(B21, FIND(" ", B21 & " ")-1)) & "*", Дані!$A$1:$F$70, 6, FALSE) -> ОТД | AH21: =$AG$18:$AG$85="АПС" -> FALSE
B22: Сергіїв Ю. І | C22: 8 | D22: в | E22: в | F22: 8 | G22: 8 | H22: 8 | I22: 8 | J22: 8 | K22: в | L22: в | M22: Л | N22: Л | O22: Л | P22: Л | Q22: Л | R22: в | S22: в | T22: 8 | U22: 8 | V22: 8 | W22: 8 | X22: пр | Y22: в | Z22: в | AA22: Відпус | AB22: Відпус | AC22: Відпус | AD22: Відпус | AE22: 8 | AF22: в | AG22: =VLOOKUP(TRIM(LEFT(B22, FIND(" ", B22 & " ")-1)) & "*", Дані!$A$1:$F$70, 6, FALSE) -> ОНК | AH22: =$AG$18:$AG$85="АПС" -> FALSE
B23: Кротова А. Г | C23: 8 | D23: в | E23: в | F23: Відр | G23: Відр | H23: Відр | I23: Відр | J23: Відр | K23: в | L23: в | M23: 4 | N23: 6 | O23: 8 | P23: 6 | Q23: 4 | R23: в | S23: в | T23: 6 | U23: 8 | V23: 6 | W23: 8 | X23: 6 | Y23: в | Z23: пр | AA23: 8 | AB23: 6 | AC23: 8 | AD23: 6 | AE23: 8 | AF23: в | AG23: =VLOOKUP(TRIM(LEFT(B23, FIND(" ", B23 & " ")-1)) & "*", Дані!$A$1:$F$70, 6, FALSE) -> ОНК | AH23: =$AG$18:$AG$85="АПС" -> FALSE
B24: Колобова Н. І | C24: 8 | D24: в | E24: в | F24: Л | G24: Л | H24: Л | I24: Л | J24: 4 | K24: 4 | L24: 4 | M24: 4 | N24: 6 | O24: 8 | P24: 6 | Q24: 4 | R24: в | S24: Відр | T24: Відр | U24: Відр | V24: Відр | W24: 8 | X24: 6 | Y24: в | Z24: в | AA24: 8 | AB24: 6 | AC24: 8 | AD24: 6 | AE24: 8 | AF24: в | AG24: =VLOOKUP(TRIM(LEFT(B24, FIND(" ", B24 & " ")-1)) & "*", Дані!$A$1:$F$70, 6, FALSE) -> ОНК | AH24: =$AG$18:$AG$85="АПС" -> FALSE
B25: Крупинов А. С | C25: 8 | D25: в | E25: в | F25: Відр | G25: Відр | H25: Відр | I25: Відр | J25: 10 | K25: в | L25: в | M25: 4 | N25: 6 | O25: 8 | P25: 6 | Q25: 4 | R25: в | S25: Відр | T25: Відр | U25: Відр | V25: Відр | W25: 8 | X25: 6 | Y25: в | Z25: в | AA25: 8 | AB25: 6 | AC25: 8 | AD25: 6 | AE25: 8 | AF25: в | AG25: =VLOOKUP(TRIM(LEFT(B25, FIND(" ", B25 & " ")-1)) & "*", Дані!$A$1:$F$70, 6, FALSE) -> ТКБ | AH25: =$AG$18:$AG$85="АПС" -> FALSE
B26: Шичко Л. В | C26: 8 | D26: в | E26: в | F26: 8 | G26: 8 | H26: 8 | I26: 8 | J26: 8 | K26: в | L26: в | M26: Л | N26: Л | O26: Л | P26: Л | Q26: Л | R26: в | S26: в | T26: 8 | U26: 8 | V26: 8 | W26: 8 | X26: пр | Y26: в | Z26: в | AA26: Відпус | AB26: Відпус | AC26: Відпус | AD26: Відпус | AE26: 8 | AF26: в | AG26: =VLOOKUP(TRIM(LEFT(B26, FIND(" ", B26 & " ")-1)) & "*", Дані!$A$1:$F$70, 6, FALSE) -> ОТД | AH26: =$AG$18:$AG$85="АПС" -> FALSE
B27: Гусев М. А | C27: 8 | D27: в | E27: в | F27: Л | G27: Л | H27: Л | I27: Л | J27: 4 | K27: 4 | L27: 4 | M27: 4 | N27: 6 | O27: 8 | P27: 6 | Q27: 4 | R27: в | S27: Відр | T27: Відр | U27: Відр | V27: Відр | W27: 8 | X27: 6 | Y27: пр | Z27: в | AA27: 8 | AB27: 6 | AC27: 8 | AD27: 6 | AE27: 8 | AF27: в | AG27: =VLOOKUP(TRIM(LEFT(B27, FIND(" ", B27 & " ")-1)) & "*", Дані!$A$1:$F$70, 6, FALSE) -> АПС | AH27: =$AG$18:$AG$85="АПС" -> TRUE
B28: Грушин А. В | C28: 8 | D28: в | E28: в | F28: Відр | G28: Відр | H28: 8 | I28: 6 | J28: 8 | K28: в | L28: в | M28: 8 | N28: 8 | O28: 8 | P28: 8 | Q28: 8 | R28: в | S28: в | T28: 8 | U28: 8 | V28: 8 | W28: Відпус | X28: Відпус | Y28: в | Z28: в | AA28: 8 | AB28: 8 | AC28: 8 | AD28: 8 | AE28: 8 | AF28: в | AG28: =VLOOKUP(TRIM(LEFT(B28, FIND(" ", B28 & " ")-1)) & "*", Дані!$A$1:$F$70, 6, FALSE) -> ТКБ | AH28: =$AG$18:$AG$85="АПС" -> FALSE
B29: Медникова В. А | C29: Відпус | D29: в | E29: в | F29: Відпус | G29: Відпус | H29: 8 | I29: 8 | J29: 8 | K29: в | L29: в | M29: 4 | N29: 8 | O29: 8 | P29: 8 | Q29: 8 | R29: в | S29: в | T29: Відр | U29: Відр | V29: 4 | W29: 8 | X29: 8 | Y29: в | Z29: в | AA29: 8 | AB29: 8 | AC29: 8 | AD29: 8 | AE29: 8 | AF29: в | AG29: =VLOOKUP(TRIM(LEFT(B29, FIND(" ", B29 & " ")-1)) & "*", Дані!$A$1:$F$70, 6, FALSE) -> ОТД | AH29: =$AG$18:$AG$85="АПС" -> FALSE
B30: Петелин М. П | C30: 6 | D30: в | E30: в | F30: 8 | G30: 8 | H30: 8 | I30: 8 | J30: 8 | K30: пр | L30: в | M30: 8 | N30: 8 | O30: 8 | P30: 8 | Q30: 8 | R30: в | S30: в | T30: 4 | U30: 4 | V30: 8 | W30: 8 | X30: 8 | Y30: в | Z30: в | AA30: 8 | AB30: 8 | AC30: 6 | AD30: 4 | AE30: 4 | AF30: в | AG30: =VLOOKUP(TRIM(LEFT(B30, FIND(" ", B30 & " ")-1)) & "*", Дані!$A$1:$F$70, 6, FALSE) -> ОТД | AH30: =$AG$18:$AG$85="АПС" -> FALSE
B31: Сидоров С. М | C31: 8 | D31: в | E31: в | F31: Л | G31: Л | H31: Л | I31: Л | J31: 4 | K31: 4 | L31: 4 | M31: 4 | N31: 6 | O31: 8 | P31: 6 | Q31: 4 | R31: в | S31: Відр | T31: Відр | U31: Відр | V31: Відр | W31: 8 | X31: 6 | Y31: в | Z31: в | AA31: 8 | AB31: 6 | AC31: 8 | AD31: 6 | AE31: 8 | AF31: в | AG31: =VLOOKUP(TRIM(LEFT(B31, FIND(" ", B31 & " ")-1)) & "*", Дані!$A$1:$F$70, 6, FALSE) -> ОНК | AH31: =$AG$18:$AG$85="АПС" -> FALSE
B32: Бахарев С. П | C32: 8 | D32: в | E32: в | F32: Л | G32: Л | H32: Л | I32: Л | J32: 4 | K32: 4 | L32: 4 | M32: 4 | N32: 6 | O32: 8 | P32: 6 | Q32: 4 | R32: в | S32: Відр | T32: Відр | U32: Відр | V32: Відр | W32: 8 | X32: 6 | Y32: в | Z32: в | AA32: 8 | AB32: 6 | AC32: 8 | AD32: 6 | AE32: 8 | AF32: в | AG32: =VLOOKUP(TRIM(LEFT(B32, FIND(" ", B32 & " ")-1)) & "*", Дані!$A$1:$F$70, 6, FALSE) -> ТКБ | AH32: =$AG$18:$AG$85="АПС" -> FALSE
B33: Михайлов В. Л | C33: Відпус | D33: в | E33: в | F33: Відпус | G33: Відпус | H33: 8 | I33: 8 | J33: 8 | K33: 7 | L33: в | M33: Відр | N33: Відр | O33: Відпус | P33: Відпус | Q33: 8 | R33: в | S33: в | T33: 8 | U33: 8 | V33: 8 | W33: 8 | X33: 8 | Y33: в | Z33: в | AA33: 8 | AB33: 8 | AC33: 10 | AD33: 8 | AE33: 8 | AF33: в | AG33: =VLOOKUP(TRIM(LEFT(B33, FIND(" ", B33 & " ")-1)) & "*", Дані!$A$1:$F$70, 6, FALSE) -> ТКБ | AH33: =$AG$18:$AG$85="АПС" -> FALSE
B34: Бородкин С. І | C34: 8 | D34: в | E34: в | F34: 8 | G34: 8 | H34: 8 | I34: 8 | J34: 8 | K34: в | L34: в | M34: Л | N34: Л | O34: Л | P34: Л | Q34: Л | R34: в | S34: в | T34: 8 | U34: 8 | V34: 8 | W34: 8 | X34: пр | Y34: в | Z34: в | AA34: Відпус | AB34: Відпус | AC34: Відпус | AD34: Відпус | AE34: 8 | AF34: в | AG34: =VLOOKUP(TRIM(LEFT(B34, FIND(" ", B34 & " ")-1)) & "*", Дані!$A$1:$F$70, 6, FALSE) -> АПС | AH34: =$AG$18:$AG$85="АПС" -> TRUE
B35: Кошкин В. П | C35: 8 | D35: в | E35: в | F35: Відр | G35: Відр | H35: Відр | I35: Відр | J35: 10 | K35: в | L35: в | M35: 4 | N35: 6 | O35: 8 | P35: 6 | Q35: 4 | R35: в | S35: Відр | T35: Відр | U35: Відр | V35: Відр | W35: 8 | X35: 6 | Y35: в | Z35: в | AA35: 8 | AB35: 6 | AC35: 8 | AD35: 6 | AE35: 8 | AF35: в | AG35: =VLOOKUP(TRIM(LEFT(B35, FIND(" ", B35 & " ")-1)) & "*", Дані!$A$1:$F$70, 6, FALSE) -> ОТД | AH35: =$AG$18:$AG$85="АПС" -> FALSE
B36: Воронов В. А | C36: 8 | D36: в | E36: в | F36: Л | G36: Л | H36: Л | I36: Л | J36: 4 | K36: 4 | L36: 4 | M36: 4 | N36: 6 | O36: 8 | P36: 6 | Q36: 4 | R36: в | S36: Відр | T36: Відр | U36: Відр | V36: Відр | W36: 8 | X36: 6 | Y36: в | Z36: в | AA36: 8 | AB36: 6 | AC36: 8 | AD36: 6 | AE36: 8 | AF36: в | AG36: =VLOOKUP(TRIM(LEFT(B36, FIND(" ", B36 & " ")-1)) & "*", Дані!$A$1:$F$70, 6, FALSE) -> ОНК
B37: Степанова Т. О | C37: Відпус | D37: в | E37: в | F37: Відпус | G37: Відпус | H37: 8 | I37: 8 | J37: 8 | K37: в | L37: в | M37: Відр | N37: Відр | O37: Відпус | P37: Відпус | Q37: 8 | R37: в | S37: в | T37: 8 | U37: 8 | V37: 8 | W37: 8 | X37: 8 | Y37: в | Z37: в | AA37: 8 | AB37: 8 | AC37: 10 | AD37: 8 | AE37: 8 | AF37: в | AG37: =VLOOKUP(TRIM(LEFT(B37, FIND(" ", B37 & " ")-1)) & "*", Дані!$A$1:$F$70, 6, FALSE) -> ОНК
B38: Кудрявцев А. П | C38: 6 | D38: в | E38: в | F38: 8 | G38: 8 | H38: 8 | I38: 8 | J38: 8 | K38: в | L38: в | M38: 8 | N38: 8 | O38: 8 | P38: 8 | Q38: 8 | R38: в | S38: в | T38: 4 | U38: 4 | V38: 8 | W38: 8 | X38: 8 | Y38: в | Z38: в | AA38: 8 | AB38: 8 | AC38: 6 | AD38: 4 | AE38: 4 | AF38: в | AG38: =VLOOKUP(TRIM(LEFT(B38, FIND(" ", B38 & " ")-1)) & "*", Дані!$A$1:$F$70, 6, FALSE) -> ОТД
B39: Кубарев С. Л | C39: Відпус | D39: в | E39: в | F39: Відпус | G39: Відпус | H39: 8 | I39: 8 | J39: 8 | K39: в | L39: в | M39: 4 | N39: 8 | O39: 8 | P39: 8 | Q39: 8 | R39: в | S39: в | T39: Відр | U39: Відр | V39: 4 | W39: 8 | X39: 8 | Y39: в | Z39: в | AA39: 8 | AB39: 8 | AC39: 8 | AD39: 8 | AE39: 8 | AF39: в | AG39: =VLOOKUP(TRIM(LEFT(B39, FIND(" ", B39 & " ")-1)) & "*", Дані!$A$1:$F$70, 6, FALSE) -> ОТД
B40: Симонов В. М | C40: 8 | D40: 7 | E40: в | F40: Відр | G40: Відр | H40: 8 | I40: 6 | J40: 8 | K40: в | L40: 7 | M40: 8 | N40: 8 | O40: 8 | P40: 8 | Q40: 8 | R40: в | S40: в | T40: 8 | U40: 8 | V40: 8 | W40: Відпус | X40: Відпус | Y40: в | Z40: в | AA40: 8 | AB40: 8 | AC40: 8 | AD40: 8 | AE40: 8 | AF40: в | AG40: =VLOOKUP(TRIM(LEFT(B40, FIND(" ", B40 & " ")-1)) & "*", Дані!$A$1:$F$70, 6, FALSE) -> ОТД
B41: Толубеев С. Г | C41: 8 | D41: в | E41: в | F41: 8 | G41: 8 | H41: 8 | I41: 8 | J41: 8 | K41: в | L41: в | M41: Л | N41: Л | O41: Л | P41: Л | Q41: Л | R41: в | S41: в | T41: 8 | U41: 8 | V41: 8 | W41: 8 | X41: пр | Y41: в | Z41: в | AA41: Відпус | AB41: Відпус | AC41: Відпус | AD41: Відпус | AE41: 8 | AF41: в | AG41: =VLOOKUP(TRIM(LEFT(B41, FIND(" ", B41 & " ")-1)) & "*", Дані!$A$1:$F$70, 6, FALSE) -> ОТД
B42: Давиденко К. І | C42: 6 | D42: в | E42: в | F42: 8 | G42: 8 | H42: 8 | I42: 8 | J42: 8 | K42: в | L42: в | M42: 8 | N42: 8 | O42: 8 | P42: 8 | Q42: 8 | R42: в | S42: в | T42: 4 | U42: 4 | V42: 8 | W42: 8 | X42: 8 | Y42: в | Z42: 7 | AA42: 8 | AB42: 8 | AC42: 6 | AD42: 4 | AE42: 4 | AF42: в | AG42: =VLOOKUP(TRIM(LEFT(B42, FIND(" ", B42 & " ")-1)) & "*", Дані!$A$1:$F$70, 6, FALSE) -> ТКБ
...

Sheet Завдання 2
B1: Завдання
B3: 1. розрахувати по відділам суму доплати, виходячи с к-сті дітей та підсумкову суму що отримав відділ з разрахунку що 13% від окладу були сплачені податки
B5: Відділи | C5: Кількість людей | D5: Сумма доплати | E5: Підсумкова сума | G5: Доплати:
B6: АПС | C6: =COUNTIF('Завдання 1'!$AG$18:$AG$85, "АПС") -> 12 | D6: =SUMIF(Дані!$F$2:$F$70, "АПС", Дані!$J$2:$J$70) -> 2000 | E6: =SUMIF(Дані!$F$2:$F$70, "АПС", Дані!$K$2:$K$70) -> 75817.76 | G6: нема чи 1 дитина | I6: 111 евро
B7: ОНК | C7: =COUNTIF('Завдання 1'!$AG$18:$AG$85, "ОНК") -> 13 | D7: =SUMIF(Дані!$F$2:$F$70, "ОНК", Дані!$J$2:$J$70) -> 1777 | E7: =SUMIF(Дані!$F$2:$F$70, "ОНК", Дані!$K$2:$K$70) -> 69432.55 | G7: від 2-х до 3-х | I7: 278 евро
B8: ОТД | C8: =COUNTIF('Завдання 1'!$AG$18:$AG$85, "ОТД") -> 21 | D8: =SUMIF(Дані!$F$2:$F$70, "ОТД", Дані!$J$2:$J$70) -> 3175 | E8: =SUMIF(Дані!$F$2:$F$70, "ОТД", Дані!$K$2:$K$70) -> 40065.61 | G8: більше 3-х | I8: 454 евро
B9: ТКБ | C9: =COUNTIF('Завдання 1'!$AG$18:$AG$85, "ТКБ") -> 22 | D9: =SUMIF(Дані!$F$2:$F$70, "ТКБ", Дані!$J$2:$J$70) -> 3286 | E9: =SUMIF(Дані!$F$2:$F$70, "ТКБ", Дані!$K$2:$K$70) -> 62826.19
B11: 2. розрахувати оклади с розподілом на Ж та М
C13: Сума оклада | D13: Середня сума оклада | E13: Сумма доплат
B14: М | C14: =SUMIF(Дані!$D$2:$D$70, "М", Дані!$G$2:$G$70) -> 200493 | D14: =AVERAGEIF(Дані!$D$2:$D$70, "М", Дані!$G$2:$G$70) -> 3855.6346 | E14: =SUMIF(Дані!$D$2:$D$70, "М", Дані!$J$2:$J$70) -> 7451
B15: Ж | C15: =SUMIF(Дані!$D$2:$D$70, "Ж", Дані!$G$2:$G$70) -> 72960 | D15: =AVERAGEIF(Дані!$D$2:$D$70, "Ж", Дані!$G$2:$G$70) -> 4560 | E15: =SUMIF(Дані!$D$2:$D$70, "Ж", Дані!$J$2:$J$70) -> 2787
B17: 3. Нарахувати премію працівникам, та звести по віділах виходячи з умови:
B18: Якщо стаж роботи перевищує 10 років, то премія складає 30% від окладу, в іншому випадку 250 евро
B20: Відділи | C20: Премія, евро
B21: АПС | C21: =SUMIF(Дані!$F$2:$F$70, "АПС", Дані!$L$2:$L$70) -> 17046.4
B22: ОНК | C22: =SUMIF(Дані!$F$2:$F$70, "ОНК", Дані!$L$2:$L$70) -> 18100
B23: ОТД | C23: =SUMIF(Дані!$F$2:$F$70, "ОТД", Дані!$L$2:$L$70) -> 8536.5
B24: ТКБ | C24: =SUMIF(Дані!$F$2:$F$70, "ТКБ", Дані!$L$2:$L$70) -> 12724.2
B26: 4. розрухвати кількість людей у відділах з разахунками по певних межах окладів
B28: Відділи | C28: до 4000 евро | D28: 4000-7500 евро | E28: більше 7500
B29: АПС | C29: =COUNTIFS(Дані!$F$2:$F$70, "АПС", Дані!$G$2:$G$70, "<4000") -> 2 | D29: =COUNTIFS(Дані!$F$2:$F$70, "АПС", Дані!$G$2:$G$70, ">=4000", Дані!$G$2:$G$70, "<=7500") -> 6 | E29: =COUNTIFS(Дані!$F$2:$F$70, "АПС", Дані!$G$2:$G$70, ">7500") -> 4
B30: ОНК | C30: =COUNTIFS(Дані!$F$2:$F$70, "ОНК", Дані!$G$2:$G$70, "<4000") -> 1 | D30: =COUNTIFS(Дані!$F$2:$F$70, "ОНК", Дані!$G$2:$G$70, ">=4000", Дані!$G$2:$G$70, "<=7500") -> 8 | E30: =COUNTIFS(Дані!$F$2:$F$70, "ОНК", Дані!$G$2:$G$70, ">7500") -> 4
B31: ОТД | C31: =COUNTIFS(Дані!$F$2:$F$70, "ОТД", Дані!$G$2:$G$70, "<4000") -> 21 | D31: =COUNTIFS(Дані!$F$2:$F$70, "ОТД", Дані!$G$2:$G$70, ">=4000", Дані!$G$2:$G$70, "<=7500") -> 0 | E31: =COUNTIFS(Дані!$F$2:$F$70, "ОТД", Дані!$G$2:$G$70, ">7500") -> 0
B32: ТКБ | C32: =COUNTIFS(Дані!$F$2:$F$70, "ТКБ", Дані!$G$2:$G$70, "<4000") -> 19 | D32: =COUNTIFS(Дані!$F$2:$F$70, "ТКБ", Дані!$G$2:$G$70, ">=4000", Дані!$G$2:$G$70, "<=7500") -> 3 | E32: =COUNTIFS(Дані!$F$2:$F$70, "ТКБ", Дані!$G$2:$G$70, ">7500") -> 0
B34: 5. розрахувати кількість людей у віддулах з разарахунками в межах років народження
B36: Відділи | C36: 1936-1956 | D36: 1957-1965 | E36: старші 1965
B37: АПС | C37: =COUNTIFS(Дані!$F$2:$F$70, "АПС", Дані!$M$2:$M$70, ">=1936", Дані!$M$2:$M$70, "<=1956") -> 9 | D37: =COUNTIFS(Дані!$F$2:$F$70, "АПС", Дані!$M$2:$M$70, ">=1957", Дані!$M$2:$M$70, "<=1965") -> 1 | E37: =COUNTIFS(Дані!$F$2:$F$70, "АПС", Дані!$M$2:$M$70, ">1965") -> 2
B38: ОНК | C38: =COUNTIFS(Дані!$F$2:$F$70, "ОНК", Дані!$M$2:$M$70, ">=1936", Дані!$M$2:$M$70, "<=1956") -> 7 | D38: =COUNTIFS(Дані!$F$2:$F$70, "ОНК", Дані!$M$2:$M$70, ">=1957", Дані!$M$2:$M$70, "<=1965") -> 3 | E38: =COUNTIFS(Дані!$F$2:$F$70, "ОНК", Дані!$M$2:$M$70, ">1965") -> 3
B39: ОТД | C39: =COUNTIFS(Дані!$F$2:$F$70, "ОТД", Дані!$M$2:$M$70, ">=1936", Дані!$M$2:$M$70, "<=1956") -> 10 | D39: =COUNTIFS(Дані!$F$2:$F$70, "ОТД", Дані!$M$2:$M$70, ">=1957", Дані!$M$2:$M$70, "<=1965") -> 8 | E39: =COUNTIFS(Дані!$F$2:$F$70, "ОТД", Дані!$M$2:$M$70, ">1965") -> 3
B40: ТКБ | C40: =COUNTIFS(Дані!$F$2:$F$70, "ТКБ", Дані!$M$2:$M$70, ">=1936", Дані!$M$2:$M$70, "<=1956") -> 15 | D40: =COUNTIFS(Дані!$F$2:$F$70, "ТКБ", Дані!$M$2:$M$70, ">=1957", Дані!$M$2:$M$70, "<=1965") -> 4 | E40: =COUNTIFS(Дані!$F$2:$F$70, "ТКБ", Дані!$M$2:$M$70, ">1965") -> 3

Sheet Завдання 3
B1: Завдання
B2: порахувати значення в колонці G | I2: Прайс-лист
A4: № п/п | B4: Найменування | C4: Обсяг партії, кг | D4: Дата продажe | E4: Вартість | I4: Найменування | J4: Ціна грн за кг
A5: 1 | B5: Капуста | C5: 5 | D5: 40460 | E5: =C5 * VLOOKUP(B5, $I$5:$J$21, 2, FALSE) -> 60 | I5: Абрикос | J5: 40
A6: 2 | B6: Ананас | C6: 10 | D6: 40459 | E6: =C6 * VLOOKUP(B6, $I$5:$J$21, 2, FALSE) -> 1200 | F6: Загальний обсяг партії, кг | G6: =SUM(C5:C29) -> 921 | I6: Ананас | J6: 120
A7: 3 | B7: ківі | C7: 13 | D7: 40463 | E7: =C7 * VLOOKUP(B7, $I$5:$J$21, 2, FALSE) -> 780 | F7: Загальна сума за партію в грн | G7: =SUM(E5:E29) -> 27973 | I7: Баклажан | J7: 29
A8: 4 | B8: Грейпфрут | C8: 14 | D8: 40461 | E8: =C8 * VLOOKUP(B8, $I$5:$J$21, 2, FALSE) -> 630 | F8: Сумарний обсяг продажів ківі | G8: =SUMIF(B5:B29, "ківі", C5:C29) -> 156 | I8: Банан | J8: 22
A9: 5 | B9: Нектарин | C9: 14 | D9: 40464 | E9: =C9 * VLOOKUP(B9, $I$5:$J$21, 2, FALSE) -> 560 | F9: Сума отримана за продажу ківі | G9: =SUMIF(B5:B29, "ківі", E5:E29) -> 9360 | I9: Грейпфрут | J9: 45
A10: 6 | B10: Манго | C10: 15 | D10: 40461 | E10: =C10 * VLOOKUP(B10, $I$5:$J$21, 2, FALSE) -> 1200 | F10: Обсяг проданого після 10 жовтня 2010 | G10: =SUMIF(D5:D29, ">10.10.2010", C5:C29) -> 578 | H10: 578 | I10: Груши | J10: 38
A11: 7 | B11: ківі | C11: 15 | D11: 40463 | E11: =C11 * VLOOKUP(B11, $I$5:$J$21, 2, FALSE) -> 900 | F11: Сума отримана після 15.10.2010 | G11: =SUMIF(D5:D29, ">15.10.2010", E5:E29) -> 5710 | I11: Капуста | J11: 12
A12: 8 | B12: Цибцля | C12: 20 | D12: 40464 | E12: =C12 * VLOOKUP(LEFT(B12, 3) & "*", $I$5:$J$21, 2, FALSE) -> 200 | F12: Обсяг проданого ківі після 10 жовтня 2010 | G12: =SUMIFS(C5:C29, B5:B29, "ківі", D5:D29, ">10.10.2010") -> 73 | I12: Картофель | J12: 8
A13: 9 | B13: ківі | C13: 23 | D13: 40454 | E13: =C13 * VLOOKUP(B13, $I$5:$J$21, 2, FALSE) -> 1380 | F13: Сума отримана від проданого ківі після 20.10.2010 | G13: =SUMIFS(E5:E29, B5:B29, "ківі", D5:D29, ">20.10.2010") -> 2700 | I13: ківі | J13: 60
A14: 10 | B14: Морков | C14: 25 | D14: 40464 | E14: =C14 * VLOOKUP(B14, $I$5:$J$21, 2, FALSE) -> 300 | F14: Обсяг проданого до 12 жовтня 2010 З обсягом партії не більше 50 кг | G14: =SUMIFS(C5:C29, D5:D29, "<12.10.2010", C5:C29, "<=50") -> 223 | H14: 223 | I14: Цибуля | J14: 10
A15: 11 | B15: Абрикос | C15: 26 | D15: 40463 | E15: =C15 * VLOOKUP(B15, $I$5:$J$21, 2, FALSE) -> 1040 | F15: Сума отриманна від продажів с 10.10.2010-15.10.2010 | G15: =SUMIFS(E5:E29, D5:D29, ">=10.10.2010", D5:D29, "<=15.10.2010") -> 10316 | I15: Манго | J15: 80
A16: 12 | B16: Цибцля | C16: 35 | D16: 40454 | E16: =C16 * VLOOKUP(LEFT(B16, 3) & "*", $I$5:$J$21, 2, FALSE) -> 350 | F16: Обсяг проданого з 10 по 22 жовтня 2010 р. | G16: =SUMIFS(C5:C29, D5:D29, ">=10.10.2010", D5:D29, "<=15.10.2010") -> 412 | H16: 462 | I16: Мандаріни | J16: 45
A17: 13 | B17: Капуста | C17: 36 | D17: 40454 | E17: =C17 * VLOOKUP(B17, $I$5:$J$21, 2, FALSE) -> 432 | F17: Кількість продаж | G17: =COUNT(C5:C29) -> 25 | I17: Морков | J17: 12
A18: 14 | B18: Груши | C18: 40 | D18: 40453 | E18: =C18 * VLOOKUP(B18, $I$5:$J$21, 2, FALSE) -> 1520 | F18: Максимальний обсяг партії, кг | G18: =MAX(C5:C29) -> 100 | I18: Нектарин | J18: 40
A19: 15 | B19: Баклажан | C19: 40 | D19: 40475 | E19: =C19 * VLOOKUP(B19, $I$5:$J$21, 2, FALSE) -> 1160 | F19: Середній обсяг партії, кг | G19: =AVERAGE(C5:C29) -> 36.84 | I19: Огурец | J19: 25
A20: 16 | B20: Персик | C20: 42 | D20: 40463 | E20: =C20 * VLOOKUP(B20, $I$5:$J$21, 2, FALSE) -> 1890 | F20: Мінімальний обсяг партії, кг | G20: =MIN(C5:C29) -> 5 | I20: Персик | J20: 45
A21: 17 | B21: Мандаріни | C21: 45 | D21: 40454 | E21: =C21 * VLOOKUP(B21, $I$5:$J$21, 2, FALSE) -> 2025 | F21: Середній обсяг продажів цибулі | G21: =AVERAGEIF(B5:B29, "циб*", C5:C29) -> 38.333333 | I21: Яблоки | J21: 23
A22: 18 | B22: ківі | C22: 45 | D22: 40476 | E22: =C22 * VLOOKUP(B22, $I$5:$J$21, 2, FALSE) -> 2700 | F22: Кількість угод з продажу ківі | G22: =COUNTIF(B5:B29, "ківі") -> 5
A23: 19 | B23: Банан | C23: 48 | D23: 40463 | E23: =C23 * VLOOKUP(B23, $I$5:$J$21, 2, FALSE) -> 1056 | F23: Кількість продажів до 12 жовтня 2010 р. з обсягом партії не більше 50 кг | G23: =COUNTIFS(D5:D29, "<12.10.2010", C5:C29, "<=50") -> 9
A24: 20 | B24: Огурец | C24: 50 | D24: 40473 | E24: =C24 * VLOOKUP(B24, $I$5:$J$21, 2, FALSE) -> 1250 | F24: Кількість угод із обсягом партії до 50 кг | G24: =COUNTIF(C5:C29, "<=50") -> 20
A25: 21 | B25: Яблоки | C25: 60 | D25: 40452 | E25: =C25 * VLOOKUP(B25, $I$5:$J$21, 2, FALSE) -> 1380 | F25: Сума отримана з угод із обсягом партії до 50 кг | G25: =SUMIF(C5:C29, "<=50", E5:E29) -> 20633
A26: 22 | B26: ківі | C26: 60 | D26: 40458 | E26: =C26 * VLOOKUP(B26, $I$5:$J$21, 2, FALSE) -> 3600 | F26: Кількість продажів ківі після 10 жовтня 2010 р. | G26: =COUNTIFS(B5:B29, "ківі", D5:D29, ">10.10.2010") -> 3
A27: 23 | B27: Цибцля | C27: 60 | D27: 40474 | E27: =C27 * VLOOKUP(LEFT(B27, 3) & "*", $I$5:$J$21, 2, FALSE) -> 600
A28: 24 | B28: Капуста | C28: 80 | D28: 40464 | E28: =C28 * VLOOKUP(B28, $I$5:$J$21, 2, FALSE) -> 960 | H28: 19
A29: 25 | B29: Картофель | C29: 100 | D29: 40464 | E29: =C29 * VLOOKUP(B29, $I$5:$J$21, 2, FALSE) -> 800
H32: 9
H34: 38.3

Sheet Завдання 4
B1: Завдання:
B2: розрахувати вартість браку та загальну вартість партії ( з вирохуванням бракованих товарів, з урахуванням доставки та знижки) | K2: (Ціна - Знижка) * (Загальна кількість - Брак) + Доставка
B3: Знижка:
B4: Поставщик "Легкість буття" дає знижку в 5%, якщо ціна більше 4000 грн на Мясорубку виробника Kenwoodik та Tefalka
B5: Поставщик "STD лидер" дає знижку в 6% на виробника Kenwoodik чи на товар "Кухонний комбайн"
B6: Поставщик "Смак Компані" дає знижку в 10% на виробника Kenwoodik на товар "Мясорубка"
B7: Виробник "Panasonika" даэ знижку 4% при ціні більше 4710
A10: Найменування | B10: Виробник | C10: Поставщик | D10: День поставки | E10: Цена за шт, грн | F10: Кількість, шт | G10: Брак, шт | H10: Вартість доставки, грн | I10: Знижка, грн | J10: Вартість браку, грн | K10: Вартість Партії, грн
A11: Печь СВЧ | B11: Goldika | C11: Смак Компані | D11: 40909 | E11: 2800 | F11: 34 | G11: 3 | H11: 750 | I11: =IF(AND(C11="Легкість буття", E11>4000, A11="Мясорубка", OR(B11="Kenwoodik", B11="Tefalka")), E11*0.05, IF(AND(C11="Смак Компані", B11="Kenwoodik", A11="Мясорубка"), E11*0.1, IF(AND(B11="Panasonika", E11>4710), E11*0.04, 0))) -> 0 | J11: =E11 * G11 -> 8400 | K11: =(E11 - I11) * (F11 - G11) + H11 -> 87550 | L11: Кофеварка | M11: Delonghik | N11: ПобутТехСила
A12: Мясорубка | B12: Panasonika | C12: Легкість буття | D12: 40911 | E12: 3880 | F12: 24 | G12: 1 | H12: 750 | I12: =IF(AND(C12="Легкість буття", E12>4000, A12="Мясорубка", OR(B12="Kenwoodik", B12="Tefalka")), E12*0.05, IF(AND(C12="Смак Компані", B12="Kenwoodik", A12="Мясорубка"), E12*0.1, IF(AND(B12="Panasonika", E12>4710), E12*0.04, 0))) -> 0 | J12: =E12 * G12 -> 3880 | K12: =(E12 - I12) * (F12 - G12) + H12 -> 89990 | L12: Кофемолка | M12: Moulinexik | N12: Легкість буття
A13: Печь СВЧ | B13: Goldika | C13: Легкість буття | D13: 40914 | E13: 2800 | F13: 38 | G13: 3 | H13: 750 | I13: =IF(AND(C13="Легкість буття", E13>4000, A13="Мясорубка", OR(B13="Kenwoodik", B13="Tefalka")), E13*0.05, IF(AND(C13="Смак Компані", B13="Kenwoodik", A13="Мясорубка"), E13*0.1, IF(AND(B13="Panasonika", E13>4710), E13*0.04, 0))) -> 0 | J13: =E13 * G13 -> 8400 | K13: =(E13 - I13) * (F13 - G13) + H13 -> 98750 | L13: Кухонный комбайн | M13: Philipka | N13: OK&KO
A14: Міксер | B14: Tefalka | C14: ПобутТехСила | D14: 40915 | E14: 900 | F14: 13 | G14: 3 | H14: 1000 | I14: =IF(AND(C14="Легкість буття", E14>4000, A14="Мясорубка", OR(B14="Kenwoodik", B14="Tefalka")), E14*0.05, IF(AND(C14="Смак Компані", B14="Kenwoodik", A14="Мясорубка"), E14*0.1, IF(AND(B14="Panasonika", E14>4710), E14*0.04, 0))) -> 0 | J14: =E14 * G14 -> 2700 | K14: =(E14 - I14) * (F14 - G14) + H14 -> 10000 | L14: Міксер | M14: Tefalka | N14: Смак Компані
A15: Міксер | B15: Kenwoodik | C15: Легкість буття | D15: 40916 | E15: 2500 | F15: 26 | G15: 0 | H15: 750 | I15: =IF(AND(C15="Легкість буття", E15>4000, A15="Мясорубка", OR(B15="Kenwoodik", B15="Tefalka")), E15*0.05, IF(AND(C15="Смак Компані", B15="Kenwoodik", A15="Мясорубка"), E15*0.1, IF(AND(B15="Panasonika", E15>4710), E15*0.04, 0))) -> 0 | J15: =E15 * G15 -> 0 | K15: =(E15 - I15) * (F15 - G15) + H15 -> 65750 | L15: Мясорубка | M15: Panasonika | N15: ТД та Компані
A16: Пароварка | B16: Tefalka | C16: Смак Компані | D16: 40916 | E16: 3900 | F16: 46 | G16: 4 | H16: 0 | I16: =IF(AND(C16="Легкість буття", E16>4000, A16="Мясорубка", OR(B16="Kenwoodik", B16="Tefalka")), E16*0.05, IF(AND(C16="Смак Компані", B16="Kenwoodik", A16="Мясорубка"), E16*0.1, IF(AND(B16="Panasonika", E16>4710), E16*0.04, 0))) -> 0 | J16: =E16 * G16 -> 15600 | K16: =(E16 - I16) * (F16 - G16) + H16 -> 163800 | L16: Пароварка | M16: Kenwoodik | N16: STD лидер
A17: Тостер | B17: Boschik | C17: OK&KO | D17: 40918 | E17: 1100 | F17: 20 | G17: 3 | H17: 750 | I17: =IF(AND(C17="Легкість буття", E17>4000, A17="Мясорубка", OR(B17="Kenwoodik", B17="Tefalka")), E17*0.05, IF(AND(C17="Смак Компані", B17="Kenwoodik", A17="Мясорубка"), E17*0.1, IF(AND(B17="Panasonika", E17>4710), E17*0.04, 0))) -> 0 | J17: =E17 * G17 -> 3300 | K17: =(E17 - I17) * (F17 - G17) + H17 -> 19450 | L17: Печь СВЧ | M17: Goldika
A18: Соковижималка | B18: Braunok | C18: Смак Компані | D18: 40921 | E18: 2360 | F18: 20 | G18: 3 | H18: 750 | I18: =IF(AND(C18="Легкість буття", E18>4000, A18="Мясорубка", OR(B18="Kenwoodik", B18="Tefalka")), E18*0.05, IF(AND(C18="Смак Компані", B18="Kenwoodik", A18="Мясорубка"), E18*0.1, IF(AND(B18="Panasonika", E18>4710), E18*0.04, 0))) -> 0 | J18: =E18 * G18 -> 7080 | K18: =(E18 - I18) * (F18 - G18) + H18 -> 40870 | L18: Соковижималка | M18: Braunok
A19: Соковижималка | B19: Delonghik | C19: ПобутТехСила | D19: 40921 | E19: 4850 | F19: 24 | G19: 1 | H19: 750 | I19: =IF(AND(C19="Легкість буття", E19>4000, A19="Мясорубка", OR(B19="Kenwoodik", B19="Tefalka")), E19*0.05, IF(AND(C19="Смак Компані", B19="Kenwoodik", A19="Мясорубка"), E19*0.1, IF(AND(B19="Panasonika", E19>4710), E19*0.04, 0))) -> 0 | J19: =E19 * G19 -> 4850 | K19: =(E19 - I19) * (F19 - G19) + H19 -> 112300 | L19: терези | M19: Sharpik
A20: Мясорубка | B20: Moulinexik | C20: Смак Компані | D20: 40922 | E20: 4100 | F20: 30 | G20: 2 | H20: 750 | I20: =IF(AND(C20="Легкість буття", E20>4000, A20="Мясорубка", OR(B20="Kenwoodik", B20="Tefalka")), E20*0.05, IF(AND(C20="Смак Компані", B20="Kenwoodik", A20="Мясорубка"), E20*0.1, IF(AND(B20="Panasonika", E20>4710), E20*0.04, 0))) -> 0 | J20: =E20 * G20 -> 8200 | K20: =(E20 - I20) * (F20 - G20) + H20 -> 115550 | L20: Тостер | M20: Boschik
A21: Соковижималка | B21: Boschik | C21: STD лидер | D21: 40923 | E21: 2500 | F21: 49 | G21: 2 | H21: 0 | I21: =IF(AND(C21="Легкість буття", E21>4000, A21="Мясорубка", OR(B21="Kenwoodik", B21="Tefalka")), E21*0.05, IF(AND(C21="Смак Компані", B21="Kenwoodik", A21="Мясорубка"), E21*0.1, IF(AND(B21="Panasonika", E21>4710), E21*0.04, 0))) -> 0 | J21: =E21 * G21 -> 5000 | K21: =(E21 - I21) * (F21 - G21) + H21 -> 117500 | L21: Чайник | M21: Samsuni
A22: Мясорубка | B22: Moulinexik | C22: Легкість буття | D22: 40924 | E22: 4100 | F22: 24 | G22: 0 | H22: 750 | I22: =IF(AND(C22="Легкість буття", E22>4000, A22="Мясорубка", OR(B22="Kenwoodik", B22="Tefalka")), E22*0.05, IF(AND(C22="Смак Компані", B22="Kenwoodik", A22="Мясорубка"), E22*0.1, IF(AND(B22="Panasonika", E22>4710), E22*0.04, 0))) -> 0 | J22: =E22 * G22 -> 0 | K22: =(E22 - I22) * (F22 - G22) + H22 -> 99150
A23: Печь СВЧ | B23: Goldika | C23: ПобутТехСила | D23: 40925 | E23: 2750 | F23: 23 | G23: 0 | H23: 750 | I23: =IF(AND(C23="Легкість буття", E23>4000, A23="Мясорубка", OR(B23="Kenwoodik", B23="Tefalka")), E23*0.05, IF(AND(C23="Смак Компані", B23="Kenwoodik", A23="Мясорубка"), E23*0.1, IF(AND(B23="Panasonika", E23>4710), E23*0.04, 0))) -> 0 | J23: =E23 * G23 -> 0 | K23: =(E23 - I23) * (F23 - G23) + H23 -> 64000
A24: Соковижималка | B24: Braunok | C24: OK&KO | D24: 40926 | E24: 2400 | F24: 23 | G24: 4 | H24: 750 | I24: =IF(AND(C24="Легкість буття", E24>4000, A24="Мясорубка", OR(B24="Kenwoodik", B24="Tefalka")), E24*0.05, IF(AND(C24="Смак Компані", B24="Kenwoodik", A24="Мясорубка"), E24*0.1, IF(AND(B24="Panasonika", E24>4710), E24*0.04, 0))) -> 0 | J24: =E24 * G24 -> 9600 | K24: =(E24 - I24) * (F24 - G24) + H24 -> 46350
A25: Міксер | B25: Moulinexik | C25: ТД та Компані | D25: 40927 | E25: 1960 | F25: 33 | G25: 0 | H25: 750 | I25: =IF(AND(C25="Легкість буття", E25>4000, A25="Мясорубка", OR(B25="Kenwoodik", B25="Tefalka")), E25*0.05, IF(AND(C25="Смак Компані", B25="Kenwoodik", A25="Мясорубка"), E25*0.1, IF(AND(B25="Panasonika", E25>4710), E25*0.04, 0))) -> 0 | J25: =E25 * G25 -> 0 | K25: =(E25 - I25) * (F25 - G25) + H25 -> 65430
A26: Пароварка | B26: Moulinexik | C26: STD лидер | D26: 40927 | E26: 1800 | F26: 46 | G26: 1 | H26: 0 | I26: =IF(AND(C26="Легкість буття", E26>4000, A26="Мясорубка", OR(B26="Kenwoodik", B26="Tefalka")), E26*0.05, IF(AND(C26="Смак Компані", B26="Kenwoodik", A26="Мясорубка"), E26*0.1, IF(AND(B26="Panasonika", E26>4710), E26*0.04, 0))) -> 0 | J26: =E26 * G26 -> 1800 | K26: =(E26 - I26) * (F26 - G26) + H26 -> 81000
A27: Мясорубка | B27: Moulinexik | C27: ТД та Компані | D27: 40928 | E27: 4100 | F27: 27 | G27: 4 | H27: 750 | I27: =IF(AND(C27="Легкість буття", E27>4000, A27="Мясорубка", OR(B27="Kenwoodik", B27="Tefalka")), E27*0.05, IF(AND(C27="Смак Компані", B27="Kenwoodik", A27="Мясорубка"), E27*0.1, IF(AND(B27="Panasonika", E27>4710), E27*0.04, 0))) -> 0 | J27: =E27 * G27 -> 16400 | K27: =(E27 - I27) * (F27 - G27) + H27 -> 95050
A28: Кофеварка | B28: Philipka | C28: Легкість буття | D28: 40930 | E28: 1280 | F28: 15 | G28: 4 | H28: 1000 | I28: =IF(AND(C28="Легкість буття", E28>4000, A28="Мясорубка", OR(B28="Kenwoodik", B28="Tefalka")), E28*0.05, IF(AND(C28="Смак Компані", B28="Kenwoodik", A28="Мясорубка"), E28*0.1, IF(AND(B28="Panasonika", E28>4710), E28*0.04, 0))) -> 0 | J28: =E28 * G28 -> 5120 | K28: =(E28 - I28) * (F28 - G28) + H28 -> 15080
A29: Кофеварка | B29: Delonghik | C29: Легкість буття | D29: 40931 | E29: 3380 | F29: 35 | G29: 3 | H29: 750 | I29: =IF(AND(C29="Легкість буття", E29>4000, A29="Мясорубка", OR(B29="Kenwoodik", B29="Tefalka")), E29*0.05, IF(AND(C29="Смак Компані", B29="Kenwoodik", A29="Мясорубка"), E29*0.1, IF(AND(B29="Panasonika", E29>4710), E29*0.04, 0))) -> 0 | J29: =E29 * G29 -> 10140 | K29: =(E29 - I29) * (F29 - G29) + H29 -> 108910
A30: Мясорубка | B30: Delonghik | C30: Легкість буття | D30: 40931 | E30: 2870 | F30: 11 | G30: 2 | H30: 1000 | I30: =IF(AND(C30="Легкість буття", E30>4000, A30="Мясорубка", OR(B30="Kenwoodik", B30="Tefalka")), E30*0.05, IF(AND(C30="Смак Компані", B30="Kenwoodik", A30="Мясорубка"), E30*0.1, IF(AND(B30="Panasonika", E30>4710), E30*0.04, 0))) -> 0 | J30: =E30 * G30 -> 5740 | K30: =(E30 - I30) * (F30 - G30) + H30 -> 26830
A31: Кофемолка | B31: Delonghik | C31: OK&KO | D31: 40933 | E31: 1080 | F31: 50 | G31: 3 | H31: 0 | I31: =IF(AND(C31="Легкість буття", E31>4000, A31="Мясорубка", OR(B31="Kenwoodik", B31="Tefalka")), E31*0.05, IF(AND(C31="Смак Компані", B31="Kenwoodik", A31="Мясорубка"), E31*0.1, IF(AND(B31="Panasonika", E31>4710), E31*0.04, 0))) -> 0 | J31: =E31 * G31 -> 3240 | K31: =(E31 - I31) * (F31 - G31) + H31 -> 50760
A32: Тостер | B32: Boschik | C32: Легкість буття | D32: 40933 | E32: 1100 | F32: 16 | G32: 4 | H32: 1000 | I32: =IF(AND(C32="Легкість буття", E32>4000, A32="Мясорубка", OR(B32="Kenwoodik", B32="Tefalka")), E32*0.05, IF(AND(C32="Смак Компані", B32="Kenwoodik", A32="Мясорубка"), E32*0.1, IF(AND(B32="Panasonika", E32>4710), E32*0.04, 0))) -> 0 | J32: =E32 * G32 -> 4400 | K32: =(E32 - I32) * (F32 - G32) + H32 -> 14200
A33: Мясорубка | B33: Kenwoodik | C33: ТД та Компані | D33: 40934 | E33: 4050 | F33: 16 | G33: 4 | H33: 1000 | I33: =IF(AND(C33="Легкість буття", E33>4000, A33="Мясорубка", OR(B33="Kenwoodik", B33="Tefalka")), E33*0.05, IF(AND(C33="Смак Компані", B33="Kenwoodik", A33="Мясорубка"), E33*0.1, IF(AND(B33="Panasonika", E33>4710), E33*0.04, 0))) -> 0 | J33: =E33 * G33 -> 16200 | K33: =(E33 - I33) * (F33 - G33) + H33 -> 49600
... A328: Тостер | B328: Delonghik | C328: Смак Компані | D328: 41272 | E328: 1950 | F328: 43 | G328: 3 | H328: 0 | I328: =IF(AND(C328="Легкість буття", E328>4000, A328="Мясорубка", OR(B328="Kenwoodik", B328="Tefalka")), E328*0.05, IF(AND(C328="Смак Компані", B328="Kenwoodik", A328="Мясорубка"), E328*0.1, IF(AND(B328="Panasonika", E328>4710), E328*0.04, 0))) -> 0 | J328: =E328 * G328 -> 5850 | K328: =(E328 - I328) * (F328 - G328) + H328 -> 78000

Sheet Завдання 5
A1: Дата | B1: Витрати | C1: Сума | D1: Одержувач
A2: 35611 | B2: Матеріали | C2: 800 | D2: АО Престиж | G2: Завдання:
A3: 37257 | B3: Накладні витрати | C3: 1000 | D3: АО ИНВЕСТ
A4: 37261 | B4: Зарплата | C4: 945 | D4: Иванов И.И. | G4: Побудувати зведену таблицю, що дозволяє подивитись сумарні
A5: 37261 | B5: Зарплата | C5: 1000 | D5: Васильева М.Ф. | G5: дані щодо кожного місяця для кожного одержувача в
A6: 37261 | B6: Зарплата | C6: 1270 | D6: Казаков С.С. | G6: залежності від статті витрат
A7: 37261 | B7: Накладні витрати | C7: 566 | D7: ТОО Надежда | G7: На підставі отриманих даних побудувати зведену діаграму
A8: 37261 | B8: Накладні витрати | C8: 600 | D8: ЗАО БИН
A9: 37262 | B9: Накладні витрати | C9: 945 | D9: АО ИНВЕСТ
A10: 37263 | B10: Матеріали | C10: 945 | D10: АО Престиж
A11: 37264 | B11: Накладні витрати | C11: 945 | D11: ТОО Надежда
A12: 37265 | B12: Накладні витрати | C12: 945 | D12: ЗАО БИН
A13: 37266 | B13: Зарплата | C13: 945 | D13: Васильева М.Ф.
A14: 37268 | B14: Зарплата | C14: 945 | D14: Иванов И.И.
A15: 37269 | B15: Накладні витрати | C15: 945 | D15: АО ИНВЕСТ
A16: 37270 | B16: Матеріали | C16: 945 | D16: АО Престиж
A17: 37271 | B17: Накладні витрати | C17: 945 | D17: ТОО Надежда
A18: 37272 | B18: Накладні витрати | C18: 945 | D18: ЗАО БИН
A19: 37273 | B19: Зарплата | C19: 945 | D19: Васильева М.Ф.
... A368: 37621 | B368: Накладні витрати | C368: 945 | D368: ТОО Надежда

Sheet Pivot table
B3: Позначки стовпців
B4: АО ИНВЕСТ | D4: АО Престиж | F4: Васильева М.Ф. | H4: ЗАО БИН | J4: Иванов И.И. | L4: Казаков С.С. | N4: ТОО Надежда | P4: Разом Загальна сума | Q4: Разом Сума з Поле1
A5: Позначки рядків | B5: Загальна сума | C5: Сума з Поле1 | D5: Загальна сума | E5: Сума з Поле1 | F5: Загальна сума | G5: Сума з Поле1 | H5: Загальна сума | I5: Сума з Поле1 | J5: Загальна сума | K5: Сума з Поле1 | L5: Загальна сума | M5: Сума з Поле1 | N5: Загальна сума | O5: Сума з Поле1
A6: 1997 | C6: 0 | D6: 800 | E6: 0 | G6: 0 | I6: 0 | K6: 0 | M6: 0 | O6: 0 | P6: 800 | Q6: 0
A7: Чер | C7: 0 | D7: 800 | E7: 0 | G7: 0 | I7: 0 | K7: 0 | M7: 0 | O7: 0 | P7: 800 | Q7: 0
A8: 2002 | B8: 50140 | C8: 0 | D8: 50740 | E8: 0 | F8: 49195 | G8: 0 | H8: 48795 | I8: 0 | J8: 48195 | K8: 0 | L8: 51230 | M8: 0 | N8: 49706 | O8: 0 | P8: 348001 | Q8: 0
A9: Січ | B9: 4780 | C9: 0 | D9: 3780 | E9: 0 | F9: 4780 | G9: 0 | H9: 4380 | I9: 0 | J9: 3780 | K9: 0 | L9: 3160 | M9: 0 | N9: 4346 | O9: 0 | P9: 29006 | Q9: 0
A10: Лют | B10: 3780 | C10: 0 | D10: 3780 | E10: 0 | F10: 3780 | G10: 0 | H10: 3780 | I10: 0 | J10: 3780 | K10: 0 | L10: 2835 | M10: 0 | N10: 3780 | O10: 0 | P10: 25515 | Q10: 0
A11: Бер | B11: 4725 | C11: 0 | D11: 3780 | E11: 0 | F11: 3780 | G11: 0 | H11: 3780 | I11: 0 | J11: 4725 | K11: 0 | L11: 4725 | M11: 0 | N11: 3780 | O11: 0 | P11: 29295 | Q11: 0
A12: Кві | B12: 3780 | C12: 0 | D12: 4725 | E12: 0 | F12: 3780 | G12: 0 | H12: 3780 | I12: 0 | J12: 3780 | K12: 0 | L12: 3780 | M12: 0 | N12: 4725 | O12: 0 | P12: 28350 | Q12: 0
A13: Тра | B13: 3780 | C13: 0 | D13: 3780 | E13: 0 | F13: 4725 | G13: 0 | H13: 4725 | I13: 0 | J13: 3780 | K13: 0 | L13: 4725 | M13: 0 | N13: 3780 | O13: 0 | P13: 29295 | Q13: 0
A14: Чер | B14: 4725 | C14: 0 | D14: 5380 | E14: 0 | F14: 3780 | G14: 0 | H14: 3780 | I14: 0 | J14: 4725 | K14: 0 | L14: 3780 | M14: 0 | N14: 3780 | O14: 0 | P14: 29950 | Q14: 0
A15: Лип | B15: 3780 | C15: 0 | D15: 4725 | E15: 0 | F15: 3780 | G15: 0 | H15: 4725 | I15: 0 | J15: 3780 | K15: 0 | L15: 3780 | M15: 0 | N15: 4725 | O15: 0 | P15: 29295 | Q15: 0
A16: Сер | B16: 3780 | C16: 0 | D16: 3780 | E16: 0 | F16: 4725 | G16: 0 | H16: 3780 | I16: 0 | J16: 4725 | K16: 0 | L16: 4725 | M16: 0 | N16: 3780 | O16: 0 | P16: 29295 | Q16: 0
A17: Вер | B17: 4725 | C17: 0 | D17: 4725 | E17: 0 | F17: 3780 | G17: 0 | H17: 3780 | I17: 0 | J17: 2835 | K17: 0 | L17: 7435 | M17: 0 | N17: 3780 | O17: 0 | P17: 31060 | Q17: 0
A18: Жов | B18: 3780 | C18: 0 | D18: 3780 | E18: 0 | F18: 4725 | G18: 0 | H18: 4725 | I18: 0 | J18: 3780 | K18: 0 | L18: 3780 | M18: 0 | N18: 4725 | O18: 0 | P18: 29295 | Q18: 0
A19: Лис | B19: 3780 | C19: 0 | D19: 3780 | E19: 0 | F19: 3780 | G19: 0 | H19: 3780 | I19: 0 | J19: 4725 | K19: 0 | L19: 4725 | M19: 0 | N19: 3780 | O19: 0 | P19: 28350 | Q19: 0
... A21: Загальний підсумок | B21: 50140 | C21: 0 | D21: 51540 | E21: 0 | F21: 49195 | G21: 0 | H21: 48795 | I21: 0 | J21: 48195 | K21: 0 | L21: 51230 | M21: 0 | N21: 49706 | O21: 0 | P21: 348801 | Q21: 0
